Processing...
Traceback (most recent call last):
  File "/home/ka/ka_iti/ka_zi9629/projects/graph_hdc/src/exp/zinc_pairs/generate_zinc_pairs.py", line 7, in <module>
    test_ds = ZincSmiles(split="test")[:500]
              ^^^^^^^^^^^^^^^^^^^^^^^^
  File "/pfs/data6/home/ka/ka_iti/ka_zi9629/projects/graph_hdc/src/datasets/zinc_smiles_generation.py", line 111, in __init__
    super().__init__(root, transform, pre_transform, pre_filter)
  File "/pfs/data6/home/ka/ka_iti/ka_zi9629/projects/graph_hdc/.pixi/envs/default/lib/python3.12/site-packages/torch_geometric/data/in_memory_dataset.py", line 81, in __init__
    super().__init__(root, transform, pre_transform, pre_filter, log,
  File "/pfs/data6/home/ka/ka_iti/ka_zi9629/projects/graph_hdc/.pixi/envs/default/lib/python3.12/site-packages/torch_geometric/data/dataset.py", line 115, in __init__
    self._process()
  File "/pfs/data6/home/ka/ka_iti/ka_zi9629/projects/graph_hdc/.pixi/envs/default/lib/python3.12/site-packages/torch_geometric/data/dataset.py", line 262, in _process
    self.process()
  File "/pfs/data6/home/ka/ka_iti/ka_zi9629/projects/graph_hdc/src/datasets/zinc_smiles_generation.py", line 134, in process
    for s in iter_smiles(Path(self.raw_paths[0])):
             ^^^^^^^^^^^^^^^^^^^^^^^^^^^^^^^^^^^^
  File "/pfs/data6/home/ka/ka_iti/ka_zi9629/projects/graph_hdc/src/datasets/zinc_smiles_generation.py", line 41, in iter_smiles
    with fp.open() as fh:
         ^^^^^^^^^
  File "/pfs/data6/home/ka/ka_iti/ka_zi9629/projects/graph_hdc/.pixi/envs/default/lib/python3.12/pathlib.py", line 1013, in open
    return io.open(self, mode, buffering, encoding, errors, newline)
           ^^^^^^^^^^^^^^^^^^^^^^^^^^^^^^^^^^^^^^^^^^^^^^^^^^^^^^^^^
FileNotFoundError: [Errno 2] No such file or directory: '/pfs/data6/home/ka/ka_iti/ka_zi9629/projects/graph_hdc/_datasets/ZincSmiles/raw/test_smile.txt'
